Workbook
Name SlicerCache_Table_1_Col_1: #N/A

Sheet Registros
A1: Fecha | B1: Pedido | C1: Identificacion | D1: PrimerNombre | E1: SegundoNombre | F1: PrimerApellido | G1: SegundoApellido | H1: Telefono | I1: FormaPago | J1: Destinatario | K1: Barrio | L1: Direccion | M1: telefonoDestino | N1: Fecha de Entrega | O1: Hora de Entrega | P1: Cantidad | Q1: Producto | R1: Precio | S1: Iva | T1: Domicilio | U1: Total | V1: Mensaje | W1: Estado | X1: Cuenta | Y1: Firmado | Z1: NombreFirma | AA1: Celular Flora | AB1: Observaciones | AC1: FacturaURL | AD1: LastModified
A2: 46067.326 | B2: 9999 | C2: 1045674390 | D2: Juan B | F2: RAPPI | H2: 572412082838 | J2: Juan B RAPPI | K2: Entrega En Tienda | L2: Entrega En Tienda - Entrega En Tienda | M2: 2412082838 | N2: 46067 | O2: 0.375 | P2: 1 | Q2: 1× Mini Heart Rosas | R2: 130000 | S2: 0 | T2: 0 | U2: 130000 | W2: Aprobado | X2: Rappi | AA2: Rappi | AB2: ID de la orden 2428717905 | AC2: =HYPERLINK("https://drive.google.com/file/d/1qmL0wbaGgLHYPFfVrBd2RR-qXIP2pBVc/view?usp=drivesdk", "Abrir_Factura") -> Abrir_Factura | AD2: 46067.328
A3: 46065.739 | B3: 20000 | C3: 1045745776 | D3: jose | F3: maestre | H3: 57573002603555 | J3: recoge en tienda | K3: Entrega En Tienda | L3: Entrega En Tienda - Entrega En Tienda | N3: 46065 | O3: 0 | P3: 1 | Q3: 1× Arreglo Personalizado | R3: 0 | S3: 0 | T3: 0 | U3: 0 | W3: Aprobado | X3: Cuentas Por Cobrar | AA3: Samsung | AB3: 1 rosa roja arreglada | AC3: =HYPERLINK("", "") | AD3: 46065.74
A4: 45980.425 | B4: 89417 | C4: 1045674063 | D4: Rafael | F4: Campis | H4: 573005140423 | J4: Entrega en tienda | K4: Entrega En Tienda | L4: Entrega en tienda - Entrega en tienda | M4: 3005140423 | N4: 45980 | O4: 0.51041667 | P4: 1 | Q4: 1× Flora Box Mediana 24 Rosas | R4: 200000 | S4: 0 | T4: 0 | U4: 200000 | W4: Aprobado | X4: Tarjeta Debito | Y4: Firmado | Z4: Tu Esposo e Hijos | AA4: Samsung | AC4: =HYPERLINK("https://drive.google.com/file/d/1Q6HcOe5lc0OK6aSMgU05LI07r-6tGCWZ/view?usp=drivesdk","Abrir_Factura") -> Abrir_Factura
A5: 45980.432 | B5: 89420 | C5: 1143144308 | D5: Jhonatan | F5: Montes | H5: 573007775110 | J5: Loraine Cárdenas | L5: Cra 48 # 70- 38 Puerta 10 clinica general del norte - Oficina | M5: 3003790967 | N5: 45980 | O5: 0.50416667 | P5: 1 | Q5: 1× Corazón Mini Surtido | R5: 120000 | S5: 0 | T5: 12000 | U5: 132000 | W5: Aprobado | X5: wompi | Y5: Firmado | Z5: Con cariño, J.M | AA5: Samsung | AC5: =HYPERLINK("https://drive.google.com/file/d/1zN5xtCMPCwxq8fnC_PznxBou3zBerbsX/view?usp=drivesdk","Abrir_Factura") -> Abrir_Factura
A6: 45980.457 | B6: 89421 | C6: 32735597 | D6: Livia | F6: Marino | H6: 573145091990 | J6: María Gabriela Marino | K6: Villa Campestre | L6: Cra 51B #135 -90 edificio villa campestre apartamentos torre 3 apto1401 - Edificio | M6: 3218539173 | N6: 45980 | O6: 0.54166667 | P6: 1 | Q6: 1× Mini Box Surtida | R6: 70000 | S6: 0 | T6: 17000 | U6: 87000 | V6: Felices 15 años Gaby. Te queremos mucho Tía Livi y Caro | W6: Aprobado | X6: Transferencia 4966 | Y6: Firmado | Z6: Felices 15 años Gaby. Te queremos mucho Con cariño Tía Livi y Caro | AA6: Huawei | AC6: =HYPERLINK("https://drive.google.com/file/d/1KU2prUvP8dEaUqtzaTtjwR1yexNQ9IT2/view?usp=drivesdk","Abrir_Factura") -> Abrir_Factura
A7: 45980.346 | B7: 89424 | C7: 1001822182 | D7: Juan | F7: Doncel | H7: 573008608059 | J7: Juan Doncel | K7: Altos de Riomar | L7: Cra 64 #98-90 casa 58 - Conjunto | M7: 3008608059 | N7: 45982 | O7: 0.43125 | P7: 1 | Q7: 1× Bouquet 6 Rosas Rojas | R7: 70000 | S7: 0 | T7: 10000 | U7: 80000 | W7: Aprobado | X7: Transferencia 4966 | Y7: Firmado | Z7: Juan Doncel | AA7: Samsung | AC7: =HYPERLINK("https://drive.google.com/file/d/1imeBapqJ5ny9GZqKzW69TeypXPi6rjI8/view?usp=drivesdk", "Abrir_Factura") -> Abrir_Factura
A8: 45980.593 | B8: 89435 | C8: 60397017 | D8: Paola | F8: Villamizar | H8: 573012340135 | J8: Isabella chaya | K8: Buenavista | L8: Calle 104 No 53 49 apto 902 - Casa | M8: 3012340135 | N8: 45981 | O8: 0.47916667 | P8: 1 | Q8: 1× Flora Box Redonda Lirio | R8: 350000 | S8: 0 | T8: 10000 | U8: 360000 | V8: No importa que tan lejos te lleven tus sueños de regreso siempre te estará esperando con todo el amor tu lugar seguro! | W8: Aprobado | X8: Transferencia 5431 | Y8: Firmado | AA8: Huawei | AC8: =HYPERLINK("https://drive.google.com/file/d/1JOWE6-h1OTfY4o5VSvwcoeevAVbqqzTV/view?usp=drivesdk","Abrir_Factura") -> Abrir_Factura
A9: 45981.549 | B9: 89439 | C9: 72278234 | D9: Juan | F9: Franco | H9: 573004867681 | J9: maria helena cure | K9: Las Delicias | L9: crarrera 44 70 107 - CECAC - Oficina | M9: 3004867681 | N9: 45982 | O9: 0.375 | P9: 1 | Q9: 1× Canasto Mediano Sweet | R9: 150000 | S9: 0 | T9: 13000 | U9: 163000 | V9: Ninguno Solo Firma | W9: Aprobado | X9: Tarjeta Debito | Y9: Firmado | Z9: Juan Franco, German Quiroz y Roberto Arenas | AA9: Huawei | AC9: =HYPERLINK("https://drive.google.com/file/d/1QG_abSdDR9pXi9vpYkZ5C5ymd8hE6ySA/view?usp=drivesdk","Abrir_Factura") -> Abrir_Factura
A10: 45981.543 | B10: 89440 | C10: 1139614281 | D10: Amanda | F10: Gonzalez | H10: 573003582590 | J10: Leonor Molinares | K10: Altos de Riomar | L10: Apto 202 - Edificio | M10: 3157412179 | N10: 45983 | O10: 0.33333333 | P10: 1 | Q10: 1× Canasto Lavanda | R10: 220000 | S10: 0 | T10: 10000 | U10: 230000 | V10: Feliz cumpleaños a la mejor mamá del mundo!! Te amo hoy y siempre. Disfruta tu día | W10: Aprobado | X10: Transferencia Bold | Y10: Firmado | Z10: Amanda | AA10: Samsung | AC10: =HYPERLINK("https://drive.google.com/file/d/1qk0cMmZLcnRbNeTRiCoQo8cqvdR5ODD5/view?usp=drivesdk","Abrir_Factura") -> Abrir_Factura
A11: 45981.638 | B11: 89464 | C11: 1085165600 | D11: Camila | F11: Colina Torres | H11: 573023562503 | J11: Camila Colina Torres | K11: Riomar | L11: Edificio Madrid, apto 6A - Edificio | M11: 3023562503 | N11: 45982 | O11: 0.33333333 | P11: 1 | Q11: 1× Mini Box Surtida | R11: 70000 | S11: 0 | T11: 0 | U11: 70000 | V11: Fabii, estamos muy orgullosas de ti!! Sigue brillando de esa manera tan hermosa, este es el primero de muchos logros para ser una doctora increíble!! Pd: recibe soon tu bono para ir a barre | W11: Aprobado | X11: Transferencia 5431 | Y11: Firmado | Z11: Con amor, Cami, hilla y Vale | AA11: Huawei | AC11: =HYPERLINK("https://drive.google.com/file/d/1xE9QAVo9UPYlWbUz-ZRnrk1l0MIID7xT/view?usp=drivesdk","Abrir_Factura") -> Abrir_Factura
A12: 45982.331 | B12: 89486 | C12: 1140892942 | D12: Fabio | F12: Barrera | H12: 573014656802 | J12: Maria Alejandra Rodriguez | K12: san vicente | L12: cra 55 # 80-285 Castellamare - Edificio | M12: 3014656802 | N12: 45983 | O12: 0.42708333 | P12: 1 | Q12: 1× Flora Box Mediana Aire | R12: 260000 | S12: 0 | T12: 6000 | U12: 266000 | V12: “Feliz navidad y prospero año nuevo. God bless America” | W12: Aprobado | X12: Transferencia Bold | Y12: Firmado | Z12: Fabio y Fendi | AA12: Samsung | AC12: =HYPERLINK("https://drive.google.com/file/d/1zkKAOl95l3oxp3Pm8x46EpnlOftDFTlN/view?usp=drivesdk","Abrir_Factura") -> Abrir_Factura
A13: 45982.331 | B13: 89488 | C13: 7083919972 | D13: Alejandra | F13: Fernandez | H13: 000000 | J13: recoge en tienda | K13: Entrega En Tienda | L13: cra. 52 # 84 - 64 | M13: flora | N13: 45982 | O13: 0.39390046 | P13: 1 | Q13: bouquet surtido | R13: 120000 | T13: 0 | U13: 120000 | W13: Aprobado | X13: Tarjeta Debito | AA13: Samsung | AC13: =HYPERLINK("https://drive.google.com/file/d/1cEUz--eJetbaruc7KpqAaq1TZiyPjLRe/view?usp=drivesdk","Abrir_Factura") -> Abrir_Factura
A14: 45982.425 | B14: 89491 | C14: 1001912485 | D14: Estefani | F14: Acosta | H14: 573045359056 | J14: Cristina duncan | K14: El Prado | L14: Cra58#66-81 apto 202 edificio prado señorial - Edificio | M14: 315 6947216 | N14: 45982 | O14: 0.58333333 | P14: 1 | Q14: 1× Canasto Mediano Sweet | R14: 150000 | S14: 0 | T14: 12000 | U14: 162000 | V14: Feliz día Dra Cristina! Gracias por todo💗 | W14: Aprobado | X14: Transferencia 5431 | Y14: Firmado | Z14: Con cariño, Stefany Acosta. | AA14: Samsung | AC14: =HYPERLINK("https://drive.google.com/file/d/1G3TdmmltYkdcNkWWYssb0Zl7KfTf_PKB/view?usp=drivesdk","Abrir_Factura") -> Abrir_Factura
A15: 45982.442 | B15: 89492 | C15: 1010094699 | D15: Maria Alejandra | F15: Rondon | H15: 573008326249 | J15: Mercedes Uribe | K15: Altos de Riomar | L15: Cra 58#86-85 / Edificio Masseba / apto 203 - Edificio | M15: 3174273757 | N15: 45982 | O15: 0.58333333 | P15: 1 | Q15: 1× Marquito Orquidea | R15: 140000 | S15: 0 | T15: 10000 | U15: 150000 | V15: Merce, te mandamos estas flores con todo nuestro cariño. Eres la más fuerte y nos llena de emocion verte salir adelante después de tantos días en la clínica. Nos alegra un montón saber que ya estás en casa y recuperándote. Ojalá cada día te sientas un poquito mejor y tengas mucha energía. Te queremos muchísimo! | W15: Aprobado | X15: Transferencia 5431 | Y15: Firmado | Z15: Andres y Lale ❤️ | AA15: Samsung | AC15: =HYPERLINK("https://drive.google.com/file/d/1m_-0GFq_FvrrLPsgg2K4_GHu9YAC7tXM/view?usp=drivesdk","Abrir_Factura") -> Abrir_Factura
A16: 45982.451 | B16: 89495 | C16: 72260542 | D16: RONIL | F16: BERDUGO CABRALES | H16: 573165266199 | J16: VALENTINA LOPEZ | K16: Puerto Colombia | L16: Calle 2c # 1 - 21 piso 1 Barrio El Ancla Puerto Colombia - Casa | M16: 3158908107 | N16: 45982 | O16: 0.54166667 | P16: 1 | Q16: 1× Flora Box Mediana Aire | R16: 260000 | S16: 0 | U16: 260000 | V16: Recibe estas flores como un abrazo lleno de orgullo y cariño en este día tan especial. ¡Felicitaciones por tu grado! Este logro es fruto de tu esfuerzo, tu disciplina y tu determinación, te deseamos un camino lleno de nuevas oportunidades, aprendizajes y éxitos. Que este sea solo el comienzo de todo lo grande que estás destinada a lograr. | W16: Aprobado | X16: Transferencia 5431 | Y16: Firmado | Z16: Con cariño, De: Jesús y Ronil | AA16: Huawei | AC16: =HYPERLINK("https://drive.google.com/file/d/1vceMbwsfA7iPkG8BZh6A5JW_EzOEF9vh/view?usp=drivesdk","Abrir_Factura") -> Abrir_Factura
A17: 45982.468 | B17: 89496 | C17: 22587251 | D17: Milena | F17: Escalante De la Cruz | H17: 573026413479 | J17: Vanesa vasco | K17: Miramar | L17: Calle 106 transversal 43-137 edificio Génova marval (Miramar ) al lado del centro comercial Miramar plaza - Edificio | M17: 3207505858 | N17: 45982 | O17: 0.55208333 | P17: 1 | Q17: 1× Corazón Mediano Surtido | R17: 200000 | S17: 0 | T17: 12000 | U17: 212000 | V17: Que bonito es compartir mi vida contigo, qué bonito es compartir risas y coleccionar experiencias a diario, qué bonito es estar con alguien que aunque no te entienda te acepte pero sobre todo te apoye, que bonito es transformar todo lo que nos hace diferente. Que bonito fue el universo al cruzarte en mi camino flaquita🐥❤️✨ I love you | W17: Aprobado | X17: Transferencia 5431 | Y17: Firmado | Z17: Milena Escalante | AA17: Huawei | AC17: =HYPERLINK("https://drive.google.com/file/d/1_Yqu76zdRdRFO82Wex3BeyII0l_UwTbr/view?usp=drivesdk","Abrir_Factura") -> Abrir_Factura
A18: 45982.608 | B18: 89519 | C18: 3232712 | D18: Mariela | F18: Lugo | H18: 573008943808 | J18: Mariela | K18: Villa Country | L18: Cl. 77b # 57 - 103 - Oficina | M18: 3008943808 | N18: 45982 | O18: 0.67916667 | P18: 1 | Q18: 1× Mini Box Claveles | R18: 70000 | S18: 0 | T18: 8000 | U18: 78000 | W18: Aprobado | X18: Transferencia 5431 | Y18: Firmado | Z18: Feliz cumpleaños para mi primera princesa, hoy cumples 12 años es un paso hermoso hacia nuevas aventuras. Que cada día recuerdes lo valiosa, fuerte y especial que eres. Siempre estaré a tu lado para apoyarte y animarte en todo lo que quieras lograr en tu vida . Te amo con todo mi corazón. att: tu Papa | AA18: Samsung | AC18: =HYPERLINK("https://drive.google.com/file/d/1oRFB1tZr_F4EBUKidTRHupRrlbfO0NZy/view?usp=drivesdk","Abrir_Factura") -> Abrir_Factura
A19: 45983.442 | B19: 89520 | C19: 1045730564 | D19: Natalia | F19: Davila | H19: 573145381698 | J19: Sheryn Saab | K19: El Golf | L19: Cra 56 # 79-342 apto 1102 Edificio San Angelo - Edificio | M19: 3135724647 | N19: 45983 | O19: 0.52569444 | P19: 1 | Q19: 1× Marquito Orquidea | R19: 140000 | S19: 0 | T19: 8000 | U19: 148000 | V19: Siempre juntas en todos los momentos importantes de nuestras vidas. Te adoro!! | W19: Aprobado | X19: Transferencia 5431 | Y19: Firmado | Z19: With love, Nat | AA19: Samsung | AC19: =HYPERLINK("https://drive.google.com/file/d/1uolEE4B83xMrWfpQLP7Fponycx3YOhNe/view?usp=drivesdk","Abrir_Factura") -> Abrir_Factura
A20: 45983.451 | B20: 89521 | C20: 1234097133 | D20: Cristhian | F20: De Marchena Rueda | H20: 573209485304 | J20: Cristhian De Marchena Rueda | K20: Santa Ana | L20: Cra 66 #58-69 - Casa | M20: 3103610622 | N20: 45983 | O20: 0.53680556 | P20: 1 | Q20: 1× Flora Box Redonda 24 Rosas de Jardín | R20: 300000 | S20: 0 | T20: 13000 | U20: 313000 | V20: Feliz cumpleaños | W20: Aprobado | X20: Transferencia 5431 | Y20: Firmado | Z20: Con cariño, tu hijo | AA20: Samsung | AC20: =HYPERLINK("https://drive.google.com/file/d/13GCSg1K0PWp5Zn3nfmnoM3eZvYNsVtrh/view?usp=drivesdk","Abrir_Factura") -> Abrir_Factura
A21: 45983.464 | B21: 89524 | C21: 1047435678 | D21: Carlos Javier | F21: Agamez Martínez | H21: 573003794847 | J21: Evelis Carreño | K21: El Parque | L21: Carrera 41 G # 47 - 18 - Casa | M21: 3003927152 | N21: 45984 | O21: 0.4375 | P21: 1 | Q21: 1× Bouquet 12 Rosas Rojas | R21: 100000 | S21: 0 | T21: 30000 | U21: 130000 | V21: Feliz cumpleaños profe, que Dios y la virgen de Fátima te Bendigan, te den muchos años de vida, salud, prosperidad, sabiduría y paciencia, para poder llegar a cada corazón de esos niños que atiendes todos los días y colocar un granito de amor en ellos para que no se sientan solos. Disfruta mucho tú día | W21: Aprobado | X21: Transferencia 4038 | Y21: Firmado | Z21: C.J.A.M | AA21: Huawei | AC21: =HYPERLINK("https://drive.google.com/file/d/1p6eTW6iNvlPr1SXObNYJDYlSZOIP9Lwy/view?usp=drivesdk","Abrir_Factura") -> Abrir_Factura
A22: 45985.453 | B22: 89576 | C22: 1234088982 | D22: Camilo | F22: Echeverri | H22: 573183514405 | J22: Carolina Segebre Abudinen | K22: Altos del Prado | L22: cra 56 Numero 79 - 342 - Edificio | M22: 3183514405 | N22: 45985 | O22: 0.48333333 | P22: 1 | Q22: 1× Flora Box Mediana Topiario | R22: 200000 | S22: 0 | T22: 8000 | U22: 208000 | V22: Muchos éxitos en tu nuevo Proyecto Mi Amor, Atentamente Camilo | W22: Aprobado | X22: Transferencia 5431 | Y22: Firmado | Z22: Camilo Echeverry | AA22: Samsung | AC22: =HYPERLINK("https://drive.google.com/file/d/1dcNInDdlULATd4QMliLUobpA26YHwr_T/view?usp=drivesdk","Abrir_Factura") -> Abrir_Factura
A23: 45985.453 | B23: 89577 | C23: 1129583788 | D23: maría | F23: araque | H23: 5712082705109 | J23: ruth del castillo | K23: El Silencio | L23: clle 71#27-56 - Casa | M23: 3168273246 | N23: 45985 | O23: 0.50972222 | P23: 1 | Q23: 1× Bouquet 6 Rosas Rojas | R23: 70000 | S23: 0 | T23: 15000 | U23: 85000 | V23: Ánimo Mamá ! No estes triste todo va a estar bien, mejórate Pronto. Estamos contigo Te Amamos mucho. De: Jake y Emma Lou | W23: Aprobado | X23: Efectivo | Y23: Firmado | Z23: De: Jake y Emma Lou | AA23: Huawei | AB23: contraentrega-efectivo | AC23: =HYPERLINK("https://drive.google.com/file/d/1rMoXOkBjsn9zyBCqRzNkFis3FMVuhoaO/view?usp=drivesdk","Abrir_Factura") -> Abrir_Factura
A24: 45985.453 | B24: 89578 | C24: 22493961 | D24: Marjorie | F24: Caballero Mendez | H24: 3006517761 | J24: Aida Palmet | K24: Villa Country | L24: Universidad Autónoma del Caribe | M24: 3208485913 | N24: 45985 | O24: 0.43204861 | P24: 1 | Q24: arreglo virgen | R24: 120000 | T24: 8000 | U24: 128000 | W24: Aprobado | X24: Transferencia Jaque | AA24: Samsung | AC24: =HYPERLINK("https://drive.google.com/file/d/11xfeJr3Y9-1YVkjdRifGX7cWsb59kdCn/view?usp=drivesdk","Abrir_Factura") -> Abrir_Factura
A25: 45985.462 | B25: 89581 | C25: 1048933991 | D25: ANDRES | F25: SOLANA | H25: 573006418722 | J25: SOFIA SOLANA | K25: Andalucía | L25: CL 85A 71A 89 - Casa | M25: 3005477557 | N25: 45985 | O25: 0.54513889 | P25: 1 | Q25: 1× Bouquet Gerbera | R25: 150000 | S25: 0 | T25: 10000 | U25: 160000 | V25: Mi amor, Hoy llega una nueva etapa en tu vida, y quiero que sepas que estamos contigo en cada paso. Hoy no solo hay un cambio en tu cuerpo, tambien un crecimiento hermoso, natural y poderoso. Estamos muy orgullosos de ti. Quiero que recuerdes siempre que sigues siendo nuestra niña: dulce, única, fuerte y especial. Nada de esto cambia quién eres; simplemente estás creciendo, floreciendo y descubriendo nuevas partes de ti misma. Y en ese camino, nunca estarás sola. Gracias por confiar en nosotros por permitirme acompañarte y por ser exactamente como eres. Cuando tengas dudas, emociones nuevas o simplemente quieras un abrazo, aquí estaremos para apoyarte, escucharte y cuidarte. Te amamos con todo mi corazón, hoy y siempre. Bienvenida a esta nueva etapa, nuestra niña hermosa. 💗 Con cariño papá y mamá. | W25: Aprobado | X25: Transferencia 4038 | Y25: Firmado | Z25: Papá y Mamá | AA25: Samsung | AB25: caja de ferrero | AC25: =HYPERLINK("https://drive.google.com/file/d/1Wmhkb61QGmThO8RT6-7R71b_6-0wR8_9/view?usp=drivesdk","Abrir_Factura") -> Abrir_Factura
A26: 45985.453 | B26: 89582 | C26: 79105208 | D26: Héctor | F26: Briceño Martínez | H26: 573017262076 | J26: Héctor Briceño Martínez | K26: Entrega En Tienda | L26: Entrega En Tienda - Entrega En Tienda | M26: 3017262076 | N26: 45987 | O26: 0.3125 | P26: 1 | Q26: 1× Flora Box Mediana 24 Rosas | R26: 200000 | S26: 0 | T26: 0 | U26: 200000 | W26: Aprobado | X26: Transferencia 5431 | Y26: Firmado | AA26: Huawei | AC26: =HYPERLINK("https://drive.google.com/file/d/1DJz8Ovx7vJW21P6_j_wHZJVvAbfwdrZc/view?usp=drivesdk","Abrir_Factura") -> Abrir_Factura
A27: 45985.505 | B27: 89583 | C27: 66870320 | D27: alejandra | F27: martinez | H27: 5713475364999 | J27: pedro pallares villarreal | K27: puerto colombia bajo orion | L27: bajo ostion,riviera del mar - Edificio | M27: 3245894951 | N27: 45985 | O27: 0.58888889 | P27: 1 | Q27: 1× Canasto Tierra | R27: 300000 | S27: 0 | T27: 80000 | U27: 380000 | W27: Aprobado | X27: Transferencia 5431 | Y27: Firmado | AA27: Samsung | AC27: =HYPERLINK("https://drive.google.com/file/d/1hHeV0P1MeKc0s6395ixVd76keDgg3xAw/view?usp=drivesdk","Abrir_Factura") -> Abrir_Factura
A28: 45985.54 | B28: 89585 | C28: 0 | D28: RAPPI | F28: Gabriela Galvan | H28: 5730111886453 | J28: gabriela galvan | K28: Entrega En Tienda | L28: Entrega En Tienda - Entrega En Tienda | M28: 30111886453 | N28: 45985 | O28: 0.62361111 | P28: 1 | Q28: 1× Bouquet 6 Rosas Rojas | R28: 70000 | S28: 0 | T28: 0 | U28: 70000 | W28: Aprobado | X28: Efectivo | Y28: Firmado | AA28: Samsung | AB28: rappi | AC28: =HYPERLINK("https://drive.google.com/file/d/1YeuemtjmN3KQZo2BgmVyj7UxFBWU85SR/view?usp=drivesdk","Abrir_Factura") -> Abrir_Factura
A29: 45985.533 | B29: 89586 | C29: 1042849973 | D29: Luis | F29: Consuegra | H29: 573106333999 | J29: Bianca Morales | K29: Ciudad Jardín Modelo | L29: Calle 80#42D1-30 - Casa | M29: 300 8001119 | N29: 45986 | O29: 0.66666667 | P29: 1 | Q29: 1× Bouquet 12 Rosas Rojas | R29: 100000 | S29: 0 | T29: 11000 | U29: 111000 | V29: Gracias por ser la mejor mamá para chiquito, ya quiero volver para que nos reunamos cómo la familia que somos ¡Los amo infinito, princesa! | W29: Aprobado | X29: Transferencia 4966 | Y29: Firmado | Z29: El amor de tu vida | AA29: Huawei | AB29: rosas rosadas | AC29: =HYPERLINK("https://drive.google.com/file/d/13RUZj9I_wS-hPmjdj9xlS4glCK03y9sV/view?usp=drivesdk","Abrir_Factura") -> Abrir_Factura
A30: 45985.598 | B30: 89590 | C30: 0 | D30: didier | F30: rodríguez | H30: 573154015161 | J30: maría nancy | K30: Altos de Riomar | L30: clle 93#42c-123 apto 1202 - Edificio | M30: 3157212330 | N30: 45985 | O30: 0.68263889 | P30: 1 | Q30: 1× Flora Box Surtida Rosas y Orquídeas | R30: 380000 | S30: 0 | T30: 10000 | U30: 390000 | W30: Aprobado | X30: Transferencia 5431 | Y30: Firmado | AA30: Samsung | AC30: =HYPERLINK("https://drive.google.com/file/d/1aPoylWWVWf5qXU1qDFNpy7Tm263YDSoO/view?usp=drivesdk","Abrir_Factura") -> Abrir_Factura
A31: 45985.587 | B31: 89591 | C31: 11240000815 | D31: Matriacanela | F31: Ojeda Villalobos | H31: 573505316838 | J31: María canela | K31: Altos de Riomar | L31: Cl. 98 #65A-54, Riomar, Barranquilla, Atlántico, Colombia - Casa | M31: 3505316838 | N31: 45987 | O31: 0.70833333 | P31: 1 | Q31: 1× Canasto Mediano Sweet | R31: 150000 | S31: 0 | T31: 10000 | U31: 160000 | V31: Hoy celebramos tu vida y lo increíble que eres. Queremos desearte un año lleno de alegría, salud, oportunidades bonitas y mucho amor. Eres una persona especial, con un corazón enorme, y mereces que todo lo bueno llegue a tu vida. Gracias por tu cariño, por tu energía tan linda y por siempre sumar. Aquí estamos para ti, hoy y siempre, con todo el amor y el apoyo del mundo. | W31: Aprobado | X31: Transferencia 5431 | Y31: Firmado | Z31: Emmanuel y canela | AA31: Samsung | AC31: =HYPERLINK("https://drive.google.com/file/d/1CgRZh5d9Cz4PSE2g53g5EbTbIzaJy10c/view?usp=drivesdk","Abrir_Factura") -> Abrir_Factura
A32: 45985.545 | B32: 89592 | C32: 1140888238 | D32: Kevin | F32: Salazar | H32: 573017262076 | J32: Kelly Sierra | K32: Villa Carolina | L32: Cr 74 # 91-120 - casa 37 - Casa | M32: 3008531481 | N32: 45987 | O32: 0.33333333 | P32: 1 | Q32: 1× Flora Box Mediana Sembrado | R32: 170000 | S32: 0 | T32: 10000 | U32: 180000 | V32: Por amarte y cuidarte Dios me quiere más. Feliz cumpleaños madre, Te amo | W32: Aprobado | X32: Transferencia 5431 | Y32: Firmado | Z32: Tu hijo | AA32: Huawei | AC32: =HYPERLINK("https://drive.google.com/file/d/1qjOjeMEq-dcRKZs1i7ayVHmG1i1qS0gv/view?usp=drivesdk","Abrir_Factura") -> Abrir_Factura
A33: 45985.603 | B33: 89593 | C33: 72357914 | D33: German | F33: Blanco | H33: 573017366162 | J33: Rochy Poveda | K33: Altos del Prado | L33: Carrera 52 # 82 -253 riu52 apt 1601 - Edificio | M33: 304 3045673 | N33: 45986 | O33: 0.45833333 | P33: 1 | Q33: 1× Flora Box Romantic Flores | R33: 190000 | S33: 0 | T33: 8000 | U33: 198000 | V33: Por muchos años de vida juntos. | W33: Aprobado | X33: Transferencia 4038 | Y33: Firmado | Z33: G.B | AA33: Samsung | AC33: =HYPERLINK("https://drive.google.com/file/d/1_gvJfscim8jqdwa1JBpi45Xlp1hCIMJ-/view?usp=drivesdk","Abrir_Factura") -> Abrir_Factura
A34: 45985.61 | B34: 89595 | C34: 1000596064 | D34: Ana Maria | F34: Cantor Daza | H34: 33666513994 | J34: Mary Luz Daza Bedoya | K34: Alameda del Río | L34: Calle 112 #43-185 apt 701 torre 4 - Edificio | M34: 33666513994 | N34: 45986 | O34: 0.3125 | P34: 1 | Q34: 1× Flora Box Mediana Tulipanes | 1× Canasto Mediano Sweet | R34: 500000 | S34: 0 | T34: 17000 | U34: 517000 | V34: Mamá, Felices 50 primaveras, me encantaría estar ahí contigo, pero aun en la distancia nuestro amor siempre será más grande. Estoy orgullosa de la mujer que eres, y solo puedo desearte que toda la luz que das siempre vuelva a tu camino. Te amo. | W34: Aprobado | X34: Transferencia 5431 | Y34: Firmado | Z34: Tu Hijita | AA34: Huawei | AC34: =HYPERLINK("https://drive.google.com/file/d/1LKP3EIegU1W4rql_LdIuDrgySi8abKqL/view?usp=drivesdk","Abrir_Factura") -> Abrir_Factura
A35: 45985.629 | B35: 89596 | C35: 1140902669 | D35: Mateo | F35: Tamara Diago | H35: 573163111155 | J35: Sophia Gomez Melo | K35: Villa Country | L35: Cra 57#78-67 Apto 102 - Edificio | M35: 3145737004 | N35: 45985 | O35: 0.7125 | P35: 1 | Q35: 1× Flora Box Mediana 24 Rosas | R35: 200000 | S35: 0 | T35: 8000 | U35: 208000 | V35: Mi amor, feliz cumpleaños, por miles de años más a tu lado, gracias por ser tan cariñosa, especial y tan incondicional. Siempre te mereces lo mejor, le doy gracias a Dios por ponerte en mi vida, te amo. | W35: Aprobado | X35: Transferencia Bold | Y35: Firmado | Z35: Mateo Támara Diago | AA35: Samsung | AC35: =HYPERLINK("https://drive.google.com/file/d/1uo1OaQOagqzpenPGAQpunkr43JRC7_I4/view?usp=drivesdk","Abrir_Factura") -> Abrir_Factura
A36: 45985.607 | B36: 89599 | C36: 1140820157 | D36: juan manuel | F36: serna | H36: 16469443749 | J36: Juan Manuel Serna | K36: El Golf | L36: Carrera 59 81 149 apto 302 - Casa | M36: 16469443749 | N36: 45985 | O36: 0.69236111 | P36: 1 | Q36: 1× Flora Box Romantic Flores | R36: 190000 | S36: 0 | T36: 8000 | U36: 198000 | V36: Hermosa, feliz 8 años de amor, de trabajar juntos nuestro camino al cielo. Te amo y por muchos años mas juntos | W36: Aprobado | X36: Transferencia Bold | Y36: Firmado | Z36: Chicho | AA36: Samsung | AC36: =HYPERLINK("https://drive.google.com/file/d/1qXmNrRtHaSf4YvNHA76W6ZrYoZI7gWmJ/view?usp=drivesdk","Abrir_Factura") -> Abrir_Factura
A37: 45985.534 | B37: 89600 | C37: 1042849973 | D37: Luis | F37: Consuegra | H37: 573106333999 | J37: Bianca Morales | K37: Ciudad Jardín Modelo | L37: Calle 80#42D1-30 - Casa | M37: 300 8001119 | N37: 45986 | O37: 0.66666667 | P37: 1 | Q37: 1× Bouquet 12 Rosas Rojas | R37: 100000 | S37: 0 | T37: 11000 | U37: 111000 | V37: Gracias por ser la mejor mamá para chiquito, ya quiero volver para que nos reunamos cómo la familia que somos ¡Los amo infinito, princesa! | W37: Aprobado | X37: Transferencia 5431 | Y37: Firmado | Z37: El amor de tu vida | AA37: Huawei | AB37: rosas rosadas | AC37: =HYPERLINK("https://drive.google.com/file/d/1dTdiX9JRBtYjep8XpSZvXwS6oxHDU9Aw/view?usp=drivesdk","Abrir_Factura") -> Abrir_Factura
A38: 45985.891 | B38: 89601 | C38: 1140838766 | D38: Carolina | F38: Zuluaga Gomez | H38: 573007895738 | J38: Nubia Gómez | K38: Altos del Prado | L38: Cra 52 # 82 - 161 Apto 4B - Ed. Asturias - Edificio | M38: 300 8509958 | N38: 45986 | O38: 0.375 | P38: 1 | Q38: 1× Flora Box Mediana Aire | R38: 260000 | S38: 0 | T38: 8000 | U38: 268000 | V38: ¡Feliz Aniversario mi amor! Son 36 años juntos, gracias por tu amor incondicional. Tu amor por siempre. | W38: Aprobado | X38: Cuentas Por Cobrar | Y38: Firmado | Z38: Rodrigo. | AA38: Samsung | AC38: =HYPERLINK("https://drive.google.com/file/d/1jS7ICHjK3Ja9Sni_4aId8l_gmK3m0wxR/view?usp=drivesdk","Abrir_Factura") -> Abrir_Factura
A39: 45985.732 | B39: 89602 | C39: 1002211373 | D39: Daniel | F39: Alvarado | H39: 16562620163 | J39: Kattia Amashta | K39: Altos del Prado | L39: Cra 52 #82-162 apto 7B - Edificio | M39: 3188833856 | N39: 45986 | O39: 0.375 | P39: 1 | Q39: 1× Guacal Surtido Lirio | R39: 160000 | S39: 0 | T39: 8000 | U39: 168000 | V39: Feliz cumpleaños a la Wonderwoman de mi vida, te amo mami! ❤️ | W39: Aprobado | X39: Transferencia 4966 | Y39: Firmado | Z39: Danny | AA39: Huawei | AC39: =HYPERLINK("https://drive.google.com/file/d/1d_GwwPImE8x23RYE5um8UpZHt6z0QyAU/view?usp=drivesdk","Abrir_Factura") -> Abrir_Factura
A40: 45985.637 | B40: 89603 | C40: 1140841620 | D40: Daniela | F40: Osorio | H40: 573188062999 | J40: Mabel Salebe | K40: Altos del Prado | L40: Carrera 49C # 80 - 255. Edificio Las Vistas. Apartamento 1B - Edificio | M40: 3168303473 | N40: 45986 | O40: 0.41666667 | P40: 1 | Q40: flora box 50 rosas rojas | R40: 400000 | S40: 0 | T40: 8000 | U40: 408000 | V40: Feliz cumpleaños mamita. Te amamos con todo nuestro 🩷 Pronto nos vemos | W40: Aprobado | X40: Transferencia 5431 | Y40: Firmado | Z40: Dani y Juli | AA40: Samsung | AC40: =HYPERLINK("https://drive.google.com/file/d/1tMa5dPjluk8kZrE1XyAxIt43SJ-nlO03/view?usp=drivesdk","Abrir_Factura") -> Abrir_Factura
...

Sheet Produccion
A1: N°Pedido | B1: Cliente | C1: Telefono | D1: Codigo | E1: Nombre_Producto | F1: Barrio | G1: Destinatario | H1: Dirección | I1: Teléfono destino | J1: Fecha de Entrega | K1: Hora de Entrega | L1: Forma de Pago | M1: Valor Cobrado | N1: Fecha | O1: Hora de Registro | P1: Estado del Pedido | Q1: Asignado | R1: Notificado | S1: Procesado | T1: Entrega En Tienda | U1: Zona | V1: Cuenta | W1: Observaciones
A2: 90797 | B2: samir vence | C2: 573204580008 | D2: 56 | E2: 1× Corazón Mediano Rosas | F2: Entrega En Tienda | G2: samir vence | H2: Entrega En Tienda - Entrega En Tienda | I2: 3204580008 | J2: 46027 | K2: 0.41666667 | M2: 220000 | N2: 46027.342 | O2: 08:14 | P2: TERMINADO | Q2: Elibeth Salgado | R2: Enviado 5/1/2026, 8:14:21 a. m. | T2: Sí | U2: Entrega En Tienda | V2: Transferencia 5431
A3: 90796 | B3: Laura Botero | C3: 573017850753 | D3: 63 | E3: 1× Guacal Surtido Lirio | F3: Altos del Prado | G3: Saida Sojo | H3: Calle 82 #59-59, Apto 303 - Edificio | I3: 3106306140 | J3: 46039 | K3: 0.66666667 | M3: 168000 | N3: 46025.823 | O3: 08:06 | P3: TERMINADO | Q3: Cristina Arrieta | R3: Enviado 5/1/2026, 8:06:56 a. m. | T3: No | U3: Zona 2 | V3: Transferencia 5431
A4: 90795 | B4: william Eichler | C4: 5.70049e+16 | D4: 21 | E4: 1× Flora Box Mediana Pastel | F4: Bethania | G4: Isabella Clavijo | H4: Calle 76 #39-39 - Casa | I4: 3011656550 | J4: 46030 | K4: 0.375 | M4: 192000 | N4: 46027.335 | O4: 08:03 | P4: TERMINADO | Q4: Elibeth Salgado | R4: Enviado 5/1/2026, 8:04:06 a. m. | T4: No | U4: Zona 2 | V4: Paypal
A5: 90794 | B5: Tatiana Guerrero Londoño | C5: 573187955699 | D5: 29 | E5: 1× Mini Box Orquidea | F5: Entrega En Tienda | G5: Tatiana Guerrero Londoño | H5: Entrega En Tienda - Entrega En Tienda | I5: 3187955699 | J5: 46027 | K5: 0 | M5: 80000 | N5: 46027.323 | O5: 07:49 | P5: TERMINADO | Q5: Elibeth Salgado | R5: Enviado 5/1/2026, 7:49:49 a. m. | T5: Sí | U5: Entrega En Tienda | V5: Efectivo | W5: Para: Juany Álvarez De: Luz Del Carmen, Margarita, Tatiana, Lorena, Balbina, Angie, Javier, Liceth, Dawi, Claudia, Adriana S., Karen, Fernando y Luz Marina.
A6: 90793 | B6: DANIEL CHAZAROWATTY | C6: 577748258571 | D6: ? | E6: 1× Bouquet 12 Rosas Rosadas | F6: Nuevo Horizonte | G6: VALENTINA LOPEZ | H6: CRA 42 # 82A-96 - Casa | I6: 3171346718 | J6: 46027 | K6: 0.375 | M6: 112000 | N6: 46027.307 | O6: 07:23 | P6: TERMINADO | Q6: Elibeth Salgado | R6: Enviado 5/1/2026, 7:23:20 a. m. | T6: No | U6: Zona 3 | V6: Transferencia 5431
A7: 90792 | B7: jorge visbal | C7: 573015013641 | D7: 29 | E7: 1× Mini Box Orquidea | F7: Villa Campestre | G7: ELEANA LOPEZ | H7: CRA 20#2A-10 CONJ, TERRA CASA 271 - Casa | I7: 3164703494 | J7: 46027 | K7: 0.375 | M7: 95000 | N7: 46027.3 | O7: 07:12 | P7: TERMINADO | Q7: Elibeth Salgado | R7: Enviado 5/1/2026, 7:13:02 a. m. | T7: No | U7: Zona 5 | V7: Transferencia 4966
A8: 90791 | B8: Julieth Martinez | C8: 573008060384 | D8: 64 | E8: 1× Marquito Orquidea | F8: Entrega En Tienda | G8: Julieth Martinez | H8: Entrega En Tienda - Entrega En Tienda | I8: 3008060384 | J8: 46027 | K8: 0.375 | M8: 140000 | N8: 46027.293 | O8: 07:02 | P8: TERMINADO | Q8: Elibeth Salgado | R8: Enviado 5/1/2026, 7:02:37 a. m. | T8: Sí | U8: Entrega En Tienda | V8: Cuentas Por Cobrar | W8: rappi
A9: 90790 | B9: vivian feris | C9: 573157264794 | D9: 95 | E9: 1× Arreglo Personalizado | F9: Entrega En Tienda | G9: vivian feris | H9: Entrega En Tienda - Entrega En Tienda | J9: 46022 | K9: 0 | M9: 182000 | N9: 46022.609 | O9: 14:37 | P9: TERMINADO | Q9: Cristina Arrieta | R9: Enviado 31/12/2025, 2:37:57 p. m. | T9: Sí | U9: Entrega En Tienda | V9: Transferencia 4966
A10: 90789 | B10: MARIA HELENA CHARRIS PEÑA | C10: 5731664237392 | D10: ? | E10: 5 canastos surtidos en amarillo | F10: caujaral | G10: maria elena | H10: caujaral - Casa | J10: 46022 | K10: 0 | M10: 1275000 | N10: 46022 | O10: 14:34 | P10: TERMINADO | Q10: Elibeth Salgado | R10: Enviado 31/12/2025, 2:34:45 p. m. | T10: No | V10: Transferencia 5431 | W10: 5 canastos surtidos
A11: 90788 | B11: Zora Virginia | C11: 13312434171 | D11: 95 | E11: 1× Arreglo Personalizado | F11: El Recreo | G11: Maria Kamila | H11: Recreo kra 34 #58-46 - Casa | J11: 46022 | K11: 0 | M11: 14000 | N11: 46022.592 | O11: 14:20 | P11: TERMINADO | Q11: James de la Cruz | R11: Enviado 31/12/2025, 2:21:08 p. m. | T11: No | U11: Zona 2 | V11: Transferencia 5431 | W11: sembrado sin orquidas y rosas rosadas
A12: 90787 | B12: Jose Castillo palacio | C12: 573004340336 | D12: 59 | E12: 1× Corazón Mediano Surtido | F12: La Cumbre | G12: VICTORIA ROMERO CASTILLO | H12: Calle 90#42e-11 casa 1 Barranquilla - Casa | J12: 46022 | K12: 0.58333333 | M12: 212000 | N12: 46022.58 | O12: 14:00 | P12: TERMINADO | Q12: Cristina Arrieta | R12: Enviado 31/12/2025, 2:00:33 p. m. | T12: No | U12: Zona 4 | V12: Transferencia 4038
A13: 90786 | B13: karen Quintero | C13: 573229447327 | D13: 95 | E13: 1× Arreglo Personalizado | F13: Entrega En Tienda | G13: karen Quintero | H13: Entrega En Tienda - Entrega En Tienda | I13: 3229447327 | J13: 46022 | K13: 0 | M13: 40000 | N13: 46022.573 | O13: 13:46 | P13: TERMINADO | Q13: Elibeth Salgado | R13: Enviado 31/12/2025, 1:46:32 p. m. | T13: Sí | U13: Entrega En Tienda | V13: Transferencia 6913 | W13: 12 rosas rojas
A14: 90785 | B14: B&A INGENIERIA Y CONSTRUCCIONES SAS empresa | C14: 573015669546 | D14: 95 | E14: 1× Arreglo Personalizado | G14: jorge agudelo | H14: ZIOON TOWERS - Casa | J14: 46022 | K14: 0 | M14: 189690 | N14: 46022.457 | O14: 13:05 | P14: TERMINADO | Q14: James de la Cruz | R14: Enviado 31/12/2025, 1:05:52 p. m. | T14: No | V14: Cuentas Por Cobrar | W14: FLORES SURTIDAS
A15: 90784 | B15: Carlos Moreno | C15: 57308162659 | D15: ? | E15: 1× Flora mini box orquidea | F15: Riomar | G15: Estefanía Pérez | H15: Cra 51 # 84-149 - Conjunto Edificio yuma - apto 303 | I15: 3208162659 | J15: 46022 | K15: 0.58333333 | M15: 90000 | N15: 46022.531 | O15: 12:57 | P15: TERMINADO | Q15: Elibeth Salgado | R15: Enviado 31/12/2025, 12:58:15 p. m. | T15: No | U15: Zona 3 | V15: Transferencia 5431
A16: 90783 | B16: claudia Castro | C16: 573106442346 | D16: 95 | E16: 1× Arreglo Personalizado | G16: claudia castro | H16: cra 58#79-121 apto 902B - Casa | I16: 3106442346 | J16: 46022 | K16: 0.54166667 | M16: 363000 | N16: 46022.446 | O16: 12:43 | P16: TERMINADO | Q16: James de la Cruz | R16: Enviado 31/12/2025, 12:44:10 p. m. | T16: No | V16: Transferencia 5431 | W16: FLORES SURTIDAS
A17: 90782 | B17: Pablo Vargas | C17: 573507547854 | D17: 51 | E17: 1× Bouquet 24 Rosas Rojas | F17: La Floresta | G17: Diana Rodriguez | H17: carrera 35 #63b-31 - Casa | I17: 3014699503 | J17: 46022 | K17: 0.58333333 | M17: 191000 | N17: 46022 | O17: 12:26 | P17: TERMINADO | Q17: James de la Cruz | R17: Enviado 31/12/2025, 12:27:06 p. m. | T17: No | U17: Zona 3 | V17: Transferencia 5431
A18: 90781 | B18: Magdolia Sánchez | C18: 573002068419 | D18: 32 | E18: 1× Mini Box Surtida | F18: Altos del Prado | G18: Magdolia Sánchez | H18: Carrera 59B#84-48 edificio vivace apto 1704 T1 - Edificio | I18: 3005903655 | J18: 46022 | K18: 0.029166667 | M18: 78000 | N18: 46022.502 | O18: 12:04 | P18: TERMINADO | Q18: Elibeth Salgado | R18: Enviado 31/12/2025, 12:05:06 p. m. | T18: No | U18: Zona 2 | V18: Transferencia 5431
A19: 90780 | B19: Mauricio Cuesta | C19: 573206349902 | D19: 95 | E19: 1× Arreglo Personalizado | F19: San Felipe | G19: Daniela Guette | H19: Calle 68 No 22c-16 - Casa | J19: 46022 | K19: 0.52847222 | M19: 135000 | N19: 46022.487 | O19: 11:47 | P19: TERMINADO | Q19: Cristina Arrieta | R19: Enviado 31/12/2025, 11:48:07 a. m. | T19: No | U19: Zona 2 | V19: Transferencia 5431 | W19: bouquet de 12 rosas lilas como el de la foto
A20: 90779 | B20: Nicolas Geraldino Aaron | C20: 573219173591 | D20: 45 | E20: 1× Bouquet Gerbera | F20: Entrega En Tienda | G20: Novia | H20: Entrega En Tienda - Entrega En Tienda | I20: 3219173591 | J20: 46022 | K20: 0 | M20: 150000 | N20: 46022.463 | O20: 11:09 | P20: TERMINADO | Q20: Elibeth Salgado | R20: Enviado 31/12/2025, 11:09:38 a. m. | T20: Sí | U20: Entrega En Tienda | V20: Efectivo
A21: 90778 | B21: Jacobo Jaramillo | C21: 573012089960 | D21: 5 | E21: 1× Flora Box Romantic Flores 24 Rosas | F21: Buenavista | G21: Jacobo Jaramillo | H21: Calle 99 C # 64 A - 45. Edif. Vallarta, apto 815 T4 - Edificio | I21: 3012089960 | J21: 46022 | K21: 0.0034722222 | M21: 230000 | N21: 46022.442 | O21: 11:00 | P21: TERMINADO | Q21: Cristina Arrieta | R21: Enviado 31/12/2025, 11:01:00 a. m. | T21: No | U21: Zona 3 | V21: Link Bold
A22: 90777 | B22: David Bohorquez rodelo | C22: 573059227701 | D22: 52 | E22: 1× Bouquet 12 Rosas Rojas | F22: Granadillo | G22: Camila gonzales | H22: Cra 45 #84-29 edificio Hispania real apart 11 - Casa | J22: 46022 | K22: 0 | M22: 109000 | N22: 46022.441 | O22: 10:57 | P22: TERMINADO | Q22: Elibeth Salgado | R22: Enviado 31/12/2025, 10:57:25 a. m. | T22: No | U22: Zona 4 | V22: Transferencia 5431
A23: 90776 | B23: Simon Hakim | C23: 573107175874 | D23: 51 | E23: 1× Bouquet 24 Rosas Rojas | F23: El Golf | G23: Salwa Chahin | H23: cra 59 # 81-149 piso 4 edificio Lenox - Edificio - Edificio | I23: 3182618317 | J23: 46022 | K23: 0.45833333 | M23: 188000 | N23: 46022.433 | O23: 10:48 | P23: TERMINADO | Q23: Elibeth Salgado | R23: Enviado 31/12/2025, 10:49:03 a. m. | T23: No | U23: Zona 3 | V23: Transferencia 5431
A24: 90775 | B24: mary nuñez | C24: 573156151131 | D24: 95 | E24: 1× Arreglo Personalizado | G24: mary nuñez | H24: Cra75a #88-71 conjunto puerto alegre apt 501G - Casa | I24: 315 6151131 | J24: 46022 | K24: 0 | M24: 40000 | N24: 46022.44 | O24: 10:35 | P24: TERMINADO | Q24: Cristina Arrieta | R24: Enviado 31/12/2025, 10:36:00 a. m. | T24: No | V24: Obsequio | W24: rosas blancas una docena CANJE
A25: 90774 | B25: Silvia Quintero | C25: 573135739800 | D25: 31 | E25: 1× Mini Box Hortensias y Mini Rosa | F25: Altos de Riomar | G25: Magdolia Sánchez | H25: Cra 59b 84 48 apto 1704 torre 1 edificio Vivace - Edificio | I25: 3005903655 | J25: 46022 | K25: 0.45833333 | M25: 78000 | N25: 46022.403 | O25: 10:18 | P25: TERMINADO | Q25: Cristina Arrieta | R25: Enviado 31/12/2025, 10:19:07 a. m. | T25: No | U25: Zona 3 | V25: Transferencia 4038
A26: 90773 | B26: Andres Mejia | C26: 573125118337 | D26: 24 | E26: 1× Flora Box Mediana Sembrado | F26: Miramar | G26: Fabiola Menco | H26: Transversal 43 No. 100-50 Edificio Napoli Torre 5 Apto 519 - Conjunto | I26: 3226529301 | J26: 46022 | K26: 0 | M26: 182000 | N26: 46022.419 | O26: 10:17 | P26: TERMINADO | Q26: Elibeth Salgado | R26: Enviado 31/12/2025, 10:17:15 a. m. | T26: No | U26: Zona 4 | V26: Transferencia 5431
A27: 90772 | B27: Laura Coronell Higgins | C27: 573113889439 | D27: ? | E27: 1× Flora Mini Plus Box cuadrada surtida pastel y topper hbd | F27: La Campiña | G27: Karilin Arteta | H27: Carrera 44 número 84 - 126 edificio Verona apto 802 - Edificio | I27: 3113432540 | J27: 46022 | K27: 0.45833333 | M27: 159000 | N27: 46022.395 | O27: 09:41 | P27: TERMINADO | Q27: Cristina Arrieta | R27: Enviado 31/12/2025, 9:41:41 a. m. | T27: No | U27: Zona 4 | V27: Transferencia 5431
A28: 90771 | B28: Sausan Osman | C28: 573186598255 | D28: 35 | E28: 1× Canasto Surtido Morado | F28: Altos de Riomar | G28: Widad Osman | H28: Cra 59 # 96-153 apto 304 - Casa | I28: 313709-2142 | J28: 46022 | K28: 0.91666667 | M28: 308000 | N28: 46022.371 | O28: 09:17 | P28: TERMINADO | Q28: James de la Cruz | R28: Enviado 31/12/2025, 9:17:54 a. m. | T28: No | U28: Zona 3 | V28: Transferencia 5431 | W28: Feliz cumpleaños a la mejor mamá, hija, hermana, cuñada y tía del mundo. Te queremos mucho. Que Dios conceda cada uno de tus deseos y te llene de bendiciones siempre.
A29: 90770 | B29: Antwan Rojas | C29: 573238135245 | D29: 52 | E29: 1× Bouquet 12 Rosas Rojas | F29: Villa Campestre | G29: Sara Catalina Rodríguez Osorio-casa 5 | H29: Transversal 3b n23-200 - Conjunto balcones de villacampestre casa 5 | I29: 3238135245 | J29: 46022 | K29: 0.45833333 | M29: 115000 | N29: 46022.373 | O29: 09:06 | P29: TERMINADO | Q29: Cristina Arrieta | R29: Enviado 31/12/2025, 9:06:28 a. m. | T29: No | U29: Zona 5 | V29: Transferencia 5431
A30: 90769 | B30: eder arrieta | C30: 573005631561 | D30: 95 | E30: 1× Arreglo Personalizado | F30: Entrega En Tienda | G30: eder arrieta | H30: Entrega En Tienda - Entrega En Tienda | I30: 300 5631561 | J30: 46022 | K30: 0.41666667 | M30: 140000 | N30: 46022.37 | O30: 08:59 | P30: TERMINADO | Q30: Elibeth Salgado | R30: Enviado 31/12/2025, 9:00:04 a. m. | T30: Sí | U30: Entrega En Tienda | V30: Transferencia 5431 | W30: un bouquet de 4 girasoles y margaritas y dos ramitos de una rosa con otra florecitas
A31: 90768 | B31: Jamid Orozco | C31: 573052891232 | D31: 41 | E31: 1× Canasto Mediano Sweet | F31: Entrega En Tienda | G31: Jamid Orozco | H31: Entrega En Tienda - Entrega En Tienda | I31: 3052891232 | J31: 46022 | K31: 0.39652778 | M31: 150000 | N31: 46022.319 | O31: 08:09 | P31: TERMINADO | Q31: Cristina Arrieta | R31: Enviado 31/12/2025, 8:10:17 a. m. | T31: Sí | U31: Entrega En Tienda | V31: Transferencia 5431
A32: 90767 | B32: Sebastian Martinez | C32: 573165316328 | D32: 3 | E32: 1× Flora Box Redonda Orquídea | F32: Ciudad Jardín Modelo | G32: Tita | H32: Cra 38d #76-60 - Casa | J32: 46022 | K32: 0.375 | M32: 361000 | N32: 46021.769 | O32: 18:58 | P32: TERMINADO | Q32: Elibeth Salgado | R32: Enviado 30/12/2025, 6:58:41 p. m. | T32: No | V32: Transferencia 5431
A33: 90766 | B33: Wilfran Hernández Gómez | C33: 573044284127 | D33: 31 | E33: 1× Mini Box Hortensias y Mini Rosa | F33: Caribe Verde | G33: LUISA FERNANDA ZAPATA | H33: Cra9g#122-94 Caribe plaza 1 torre 1 apto 702 - Casa | I33: 3044284127 | J33: 46022 | K33: 0 | M33: 95000 | N33: 46021 | O33: 18:38 | P33: TERMINADO | Q33: Cristina Arrieta | R33: Enviado 30/12/2025, 6:38:40 p. m. | T33: No | U33: Zona 6 | V33: Transferencia 5431 | W33: Quisiera que fuera envuelta en un papel elegante
A34: 90765 | B34: eli franco | C34: 573013903481 | D34: 95 | E34: 1× Arreglo Personalizado | F34: Entrega En Tienda | G34: eli franco | H34: Entrega En Tienda - Entrega En Tienda | I34: 3013903481 | J34: 46021 | K34: 0 | M34: 39000 | N34: 46021 | O34: 18:35 | P34: TERMINADO | Q34: Elibeth Salgado | R34: Enviado 30/12/2025, 6:35:53 p. m. | T34: Sí | U34: Entrega En Tienda | V34: Datafono Credibanco | W34: flores surtidas
A35: 90764 | B35: lourdes atique | C35: 573205420119 | D35: 95 | E35: 1× Arreglo Personalizado | F35: Altos de Riomar | G35: stephanie saieh | H35: Cra 58 no 90-88 Casa - Casa | I35: 3205420119 | J35: 46022 | K35: 0.41666667 | M35: 238000 | N35: 46021 | O35: 17:29 | P35: TERMINADO | Q35: Adriana Suarez | R35: Enviado 30/12/2025, 5:30:13 p. m. | T35: No | U35: Zona 3 | V35: Cuentas Por Cobrar | W35: 5 paq.de soliaster,3 paqu. de eucalipto,2 paqu.de fuyi,1 paq.de pinopio amarillo,5 rosas,2 paq.de boca de dragon blanca,2 paq.de ruscus,1 paq,de aster,12 piñas.
A36: 90763 | B36: laura paternostro | C36: 573183607759 | D36: 95 | E36: 1× Arreglo Personalizado | F36: Entrega En Tienda | G36: laura paternostro | H36: Entrega En Tienda - Entrega En Tienda | J36: 46021 | K36: 0 | M36: 15000 | N36: 46021 | O36: 17:01 | P36: TERMINADO | Q36: Elibeth Salgado | R36: Enviado 30/12/2025, 5:01:42 p. m. | T36: Sí | U36: Entrega En Tienda | V36: Datafono Credibanco | W36: medio paquete de pino
A37: 90762 | B37: david rodas | C37: 575667005 | D37: 52 | E37: 1× Bouquet 12 Rosas Rojas | F37: Bostón | G37: david rodas | H37: Entrega En Tienda - Entrega En Tienda | I37: 5667005 | J37: 46021 | K37: 0 | M37: 100000 | N37: 46021.707 | O37: 17:00 | P37: TERMINADO | Q37: Elibeth Salgado | R37: Enviado 30/12/2025, 5:00:54 p. m. | T37: No | U37: Zona 2 | V37: Datafono Credibanco
A38: 90761 | B38: indira cañas | C38: 573106242990 | D38: 95 | E38: 1× Arreglo Personalizado | F38: Miramar | G38: indira cañas | H38: tv 57#99-180 apto 703 select | I38: 3106242990 | J38: 46022 | K38: 0.41666667 | M38: 162000 | N38: 46021.687 | O38: 16:38 | P38: TERMINADO | Q38: Adriana Suarez | R38: Enviado 30/12/2025, 4:39:06 p. m. | T38: No | U38: Zona 4 | V38: Transferencia 4038 | W38: 5 hortencias,1 paq. de pino,1 de eucalipto,1 de astromelia,2 de hipérico,18 rosas rojas.
A39: 90760 | B39: Jesus Camaño | C39: 573046167890 | D39: 31 | ? | E39: 1× Mini Box Hortensias y Mini Rosa | 1× Marquito Girasol | F39: Paraíso | G39: Jesús Camaño | H39: Carrera 63 #77C-177 - Casa | I39: 3046167890 | J39: 46021 | K39: 0.70833333 | M39: 200000 | N39: 46021.669 | O39: 16:27 | P39: TERMINADO | Q39: Elibeth Salgado | R39: Enviado 30/12/2025, 4:27:49 p. m. | T39: No | U39: Zona 3 | V39: Transferencia 4966 | W39: Feliz cumpleaños mi princesa hermosa. Te amo
A40: 90759 | B40: yanelis alvarez | C40: 573008907262 | D40: 31 | E40: 1× Mini Box Hortensias y Mini Rosa | F40: Paraíso | G40: Camila | H40: Cr 71 80- 25 paraíso - Casa | I40: 3013021116 | J40: 46021 | K40: 0.64722222 | M40: 80000 | N40: 46021.611 | O40: 14:54 | P40: TERMINADO | Q40: Cristina Arrieta | R40: Enviado 30/12/2025, 2:54:30 p. m. | T40: No | U40: Zona 3 | V40: Transferencia 5431
...

Sheet Domicilios
A1: N°Pedido | B1: Cliente | C1: Telefono | D1: Producto | E1: Dirección de Entrega | F1: Barrio | G1: Destinatario | H1: TelefonoDestino | I1: Domiciliario | J1: TelefonoDomiciliario | K1: Externo | L1: Estado Domicilio | M1: FechaAsignación | N1: FechaEntrega | O1: Observaciones | P1: Zona | Q1: Foto | R1: Hora_Salida | S1: Hora_Entrega
A2: 92993 | B2: Danna sanjuanelo | C2: 573003346799 | D2: 1× Corazón Mini Surtido M/12 | E2: Recoger en Tienda | F2: Recoger en Tienda | G2: Danna sanjuanelo | H2: 573003346799 | K2: 46089.687 | L2: Pendiente | M2: 03/08/2026 16:29:47 | N2: 03/08/2026 - 17:00:00 | R2: 46076.613 | S2: 46076.645
A3: 92987 | B3: alex avilez | C3: 573205423436 | D3: 1 BOUQUET X 12 ROSAS ROSADAS Y BLANCAS | E3: Calle 110 No 49e-86 condominio isabella - APTO: 301 TORRE: 1 | F3: Villa Santos | G3: DANIELA JARABA | H3: 573008834542 | I3: EXT - Juan David | K3: 46089.669 | L3: En Ruta | M3: 03/08/2026 16:03:52 | N3: 03/08/2026 - 16:30:00 | P3: Zona 4 | R3: 46076.613 | S3: 46076.627
A4: 92986 | B4: María andrea Rodríguez | C4: 573006498138 | D4: 1× Mini Box Orquidea M/22 | E4: Cra 59b #91-74 - edificio Trivento apto 1201 | F4: Altos de Riomar | G4: Isabella | H4: 573157496731 | I4: EXT - Moni | K4: 46089.7 | L4: Entregado | M4: 03/08/2026 16:47:54 | N4: 03/08/2026 - 04:00:00 | P4: Zona 3 | R4: 46074.449 | S4: 46074.45
A5: 92983 | B5: Mauricio Andrés Figueroa Ricardo | C5: 573148167126 | D5: 1× Bouquet Aire M/7 | E5: Calle 70B#41-87 - Clínica Santa ana | F5: Delicias | G5: Mauricio Figueroa | H5: 573148167126 | K5: 46089.673 | L5: Pendiente | M5: 03/08/2026 16:08:32 | N5: 03/08/2026 - 16:00:00 | R5: 46074.46 | S5: 46076.456
A6: 92980 | B6: Danna sanjuanelo | C6: 573003346799 | D6: 1× Flora Mini Plus Box Redonda M/28 | E6: Cra 50#61-172 | F6: El Prado | G6: Mileidy segura | H6: 573114100464 | I6: EXT - William Osorio | K6: 46089.672 | L6: Entregado | M6: 03/08/2026 16:07:24 | N6: 03/08/2026 - 17:00:00 | P6: Zona 1 | R6: 46076.613 | S6: 46076.623
A7: 92979 | B7: Joiker Alejandro | C7: 573126314688 | D7: 1× Mini Box Orquidea M/22 | 1× Ferrero Rocher 8 und | E7: Recoger en Tienda | F7: Recoger en Tienda | G7: Joiker Alejandro | H7: 573126314688 | K7: 46089.678 | L7: Pendiente | M7: 03/08/2026 16:16:50 | N7: 03/08/2026 - 17:00:00 | R7: 46076.528 | S7: 46076.583
A8: 92978 | B8: Javier Chacon | C8: 573117169931 | D8: 1× Corazón Mini Surtido M/12 | 1× Oso de Peluche | E8: Carrera 52 #106-140 - Casa 94 | F8: Riomar | G8: Madeleine Vecino | H8: 573004400740 | K8: 46089.651 | L8: En Ruta | M8: 03/08/2026 15:37:11 | N8: 03/08/2026 - 04:00:00 | P8: Zona 3
A9: 92977 | B9: David Gomez | C9: 573044408100 | D9: 1× Mini Box Orquidea M/22 | E9: Calle 99 #56-48 edificio Santillana - Torre 2 apto 1606 | F9: Altos de Riomar | G9: Santillana | H9: 573044408100 | I9: EXT - Moni | K9: 46089.683 | L9: Entregado | M9: 03/08/2026 16:23:45 | N9: 03/08/2026 - 04:00:00 | P9: Zona 3 | R9: 46089.717 | S9: 46089.718
A10: 92975 | B10: Andrés Serret | C10: 573015889880 | D10: 1× Mini Box Clavel Fucsia M/20 | E10: Recoger en Tienda | F10: Recoger en Tienda | G10: Andrés Serret | H10: 573015889880 | K10: 46089.616 | L10: Pendiente | M10: 03/08/2026 14:47:21 | N10: 03/08/2026 - 00:00:00
A11: 92974 | B11: Nicolás Fuentes | C11: 573155928344 | D11: 1× Mini Box Orquidea M/22 | E11: Cra. 58 #98-71 | F11: Riomar | G11: Raquel Padilla Quintana | I11: EXT - Moni | K11: 46089.679 | L11: Entregado | M11: 03/08/2026 16:17:11 | N11: 03/08/2026 - 00:00:00 | P11: Zona 3 | R11: 46089.716 | S11: 46076.526
A12: 92973 | B12: Nico Sanchez | C12: 3004612667 | D12: 1× Corazón Mini Surtido M/12 | E12: Calle 1A #30-61 - Apto 511 torre 2 | F12: Riomar | G12: Sofía vueltas | H12: 573044233449 | I12: Elvis | K12: 46089.65 | L12: En Ruta | M12: 03/08/2026 15:36:16 | N12: 03/08/2026 - 16:00:00 | P12: Zona 3
A13: 92971 | B13: Adrián Raya Carmona | C13: 34644380068 | D13: 1× Guacal Hortensias M/13 | 1× Mini Box Orquidea M/22 | E13: Calle 68 # 32 - 56 - Apto 2 | F13: Olaya | G13: Anna Stand | H13: 573508401213 | I13: Oscar | K13: 46089.673 | L13: Entregado | M13: 03/08/2026 16:09:14 | N13: 03/08/2026 - 04:30:00 | P13: Zona 2
A14: 92969 | B14: Samia Maloof | C14: 573007524271 | D14: 1× Mini Box Orquidea M/22 | 1× Bouquet 6 Rosas Rojas M/10 | E14: Cra 57 # 81 100 - Casa | F14: El Golf | G14: Samia | H14: 573007524271 | I14: EXT - William Osorio | K14: 46089.66 | L14: Entregado | M14: 03/08/2026 15:50:08 | N14: 03/08/2026 - 15:00:00 | P14: Zona 3 | R14: 46076.574 | S14: 46076.574
A15: 92968 | B15: Nico Sanchez | C15: 30043004612667 | D15: 1× Corazón Mini Surtido M/12 | E15: Cra 52#106-140 - Castellana real | F15: Riomar | G15: Emna Sánchez | H15: 573004612667 | I15: Elvis | K15: 46089.618 | L15: En Ruta | M15: 03/08/2026 14:50:29 | N15: 03/08/2026 - 16:00:00 | P15: Zona 3 | R15: 46076.575 | S15: 46076.575
A16: 92967 | B16: Juan pablo Muñoz gomez | C16: 573013894849 | D16: 1× Flora Box Romantic Flores 12 Rosas M/18 | E16: Carrera52#132-87 - Casa 28 | F16: Villa Campestre | G16: Marasha elite | H16: 573013894849 | I16: Elvis | K16: 46089.654 | L16: En Ruta | M16: 03/08/2026 15:41:10 | N16: 03/08/2026 - 04:00:00 | P16: Zona 5 | R16: 46078.382 | S16: 46078.382
A17: 92966 | B17: Yamal Saghair | C17: 573008446022 | D17: 1× Mini Box Orquidea M/22 | E17: Calle 97 #42f-43 Mirador del mar 2 - Torre 1 apto 204 | F17: Miramar | G17: Keyla | H17: 573012615857 | K17: 46089.63 | L17: Pendiente | M17: 03/08/2026 15:07:53 | N17: 03/08/2026 - 16:00:00 | P17: Zona 4 | R17: 46076.607 | S17: 46076.607
A18: 92965 | B18: Gerardo Ortega | C18: 573208395916 | D18: 1× Bouquet 24 Rosas Rojas M/8 | E18: Cra58#96-158 - Apto 1201 | F18: Altos de Riomar | G18: Micaela Adelaida | H18: 573004056966 | I18: EXT - Moni | K18: 46089.615 | L18: Entregado | M18: 03/08/2026 14:45:12 | N18: 03/08/2026 - 15:00:00 | P18: Zona 3 | R18: 46076.64 | S18: 46076.64
A19: 92964 | B19: Gustavo Cantero | C19: 573009477121 | D19: 1× Bouquet 12 Rosas Rojas M/9 | E19: calle 77 #57-85 - villa fontana , casa 13 | F19: Villa Country | G19: Angie Rincon | H19: 573053042125 | I19: Oscar | K19: 46089.586 | L19: Entregado | M19: 03/08/2026 14:04:09 | N19: 03/08/2026 - 04:00:00 | P19: Zona 3 | R19: 46076.654 | S19: 46076.654
A20: 92963 | B20: Daniel Maestre | C20: 573188709938 | D20: 1× Bouquet 24 Rosas Rojas M/8 | E20: Calle 104 #49e-70 - Casa 1 | F20: Villa Santos | G20: Ana serrano | H20: 573215461190 | I20: EXT - Moni | K20: 46089.607 | L20: Entregado | M20: 03/08/2026 14:33:47 | N20: 03/08/2026 - 16:00:00 | P20: Zona 4 | R20: 46076.686 | S20: 46076.686
A21: 92962 | B21: Jose Llanos | C21: 573052325427 | D21: 1× Mini Box Orquidea M/22 | 1× Mini Box Clavel Fucsia M/20 | E21: Recoger en Tienda | F21: Recoger en Tienda | G21: Jose Llanos | H21: 573052325427 | K21: 46089.586 | L21: Pendiente | M21: 03/08/2026 14:03:50 | N21: 03/08/2026 - 02:00:00 | R21: 46076.759 | S21: 46076.759
A22: 92961 | B22: Ana María Martínez | C22: 573152727192 | D22: 1× Mini Box Orquidea M/22 | E22: Cra 64d #85-179 - Edificio macarol apto 501 | F22: Altos de Riomar | G22: Ana Marcela Martinez | H22: 573156165550 | I22: EXT - Moni | K22: 46089.663 | L22: Entregado | M22: 03/08/2026 15:54:27 | N22: 03/08/2026 - 15:00:00 | P22: Zona 3 | R22: 46077.359 | S22: 46077.359
A23: 92960 | B23: Carlos Bayuelo | C23: 310 6376698 | D23: 1× Mini Box Orquidea M/22 | 1× Flora Mini Plus Box Redonda M/28 | 1× Corazón Mini Surtido M/12 | E23: Recoger en Tienda | F23: Recoger en Tienda | G23: Carlos Bayuelo | H23: 573106376698 | K23: 46089.673 | L23: Pendiente | M23: 03/08/2026 16:08:44 | N23: 03/08/2026 - 03:00:00 | R23: 46077.48 | S23: 46077.48
A24: 92959 | B24: Pedro Marquez | C24: 573105585460 | D24: 1× Encanto lila M/15 | E24: Cr 48 no 100-78 - Edifio Lanzerotti Apto 201 | F24: Villa Santos | G24: Daniela Orozco | H24: 573105585460 | I24: Elvis | K24: 46089.625 | L24: En Ruta | M24: 03/08/2026 14:59:54 | N24: 03/08/2026 - 04:00:00 | P24: Zona 4 | R24: 46077.386 | S24: 46077.386
A25: 92958 | B25: Juan Esteban Camacho Reyes | C25: 573005273265 | D25: 1× Corazón Mini Surtido M/12 | 1× Ferrero Rocher 8 und | E25: Calle 88#42e43 - Casa 2 pisos | F25: Los Nogales | G25: Marcela Ariza | H25: 573012112234 | I25: EXT - Moni | K25: 46089.595 | L25: Entregado | M25: 03/08/2026 14:17:17 | N25: 03/08/2026 - 15:00:00 | P25: Zona 4 | R25: 46077.405 | S25: 46077.405
A26: 92957 | B26: Madeleine Vecino | C26: 573004400740 | D26: 1× Mini Box Orquidea M/22 | E26: Carrera 52 # 106-140 - Casa 94 Conjunto castellana real | F26: Villa Santos | G26: Madelein Chacón | H26: 573004400740 | I26: Elvis | K26: 46089.617 | L26: En Ruta | M26: 03/08/2026 14:48:32 | N26: 03/08/2026 - 15:00:00 | P26: Zona 4 | R26: 46077.439 | S26: 46077.439
A27: 92956 | B27: Ronald Bayena | C27: 573154447302 | D27: 1× Bouquet 12 Rosas Rojas M/9 | 1× Vino Blanco Terra Vega | E27: Calle 82a#42-09 | F27: Los Nogales | G27: Sophia Ludovica | H27: 573045724174 | I27: EXT - Moni | K27: 46089.623 | L27: Entregado | M27: 03/08/2026 14:57:49 | N27: 03/08/2026 - 03:00:00 | P27: Zona 4 | R27: 46077.483 | S27: 46077.483
A28: 92955 | B28: Leonardo Daniel Meza Cantillo | C28: 3107063615 | D28: 1× Corazón Mini Surtido M/12 | E28: Cra 50 #74-126 - Edificio gaviotas | F28: Villa Country | G28: Shaila Arrieta | H28: 573005435875 | I28: EXT - William Osorio | K28: 46089.704 | L28: Entregado | M28: Sun Mar 08 2026 16:56:31 GMT-0500 (hora estándar de Colombia) | N28: 03/08/2026 - 15:00:00 | P28: Zona 3 | R28: 46077.517 | S28: 46077.517
A29: 92954 | B29: Franklin Pineres | C29: 573116629388 | D29: 1× Flora Box Sembrado 9 Rosas M/20 | E29: Cr 26c7 # 75b - 50 - Casa blanca 1er Piso | F29: El Silencio | G29: Emily Acuña | H29: 573163764650 | I29: Oscar | K29: 46089.63 | L29: Entregado | M29: 03/08/2026 15:07:28 | N29: 03/08/2026 - 03:00:00 | P29: Zona 2 | R29: 46077.617 | S29: 46077.617
A30: 92953 | B30: Emelis Orozco | C30: 573052429073 | D30: 1× Bouquet 12 Rosas Rojas M/9 | E30: Cra. 59b # 58 - 57 - Casa | F30: El Prado | G30: Isabel Cristina | H30: 573002866923 | I30: EXT - Javier | K30: 46089.641 | L30: Entregado | M30: 03/08/2026 15:22:36 | N30: 03/08/2026 - 16:00:00 | P30: Zona 1 | R30: 46077.621 | S30: 46077.621
A31: 92951 | B31: Juan Diego Molina Peñate | C31: 573043117743 | D31: 1× Cerámica Sweet Pea M/16 | E31: Cra. 30 #2C - 196 Edif River Place Torre 1 APTO 304 | F31: Villa Campestre | G31: Juan Diego Molina Peñate | H31: 573043117743 | I31: Elvis | K31: 46089.616 | L31: En Ruta | M31: 03/08/2026 14:46:34 | N31: 03/08/2026 - 15:00:00 | P31: Zona 5 | R31: 46077.621 | S31: 46077.621
A32: 92950 | B32: Geraldine Herrera | C32: 573150491518 | D32: 1× Mini Box Orquidea M/22 | E32: Recoger en Tienda | F32: Recoger en Tienda | G32: ISABEL PEÑA PUCHE | H32: 573150491518 | K32: 46089.575 | L32: Pendiente | M32: 03/08/2026 13:47:34 | N32: 03/08/2026 - 13:00:00 | R32: 46077.643 | S32: 46077.643
A33: 92949 | B33: Esteban Correa | C33: 573015245531 | D33: Cerámica Sweet Pea M/16 | E33: Carrera 59#96-78 - Edif ferrara apto10A | F33: Altos de Riomar | G33: Liliana Payares | H33: 573184187111 | I33: Elvis | K33: 46089.661 | L33: En Ruta | M33: 03/08/2026 15:51:12 | N33: 03/08/2026 - 14:00:00 | P33: Zona 3 | R33: 46077.656 | S33: 46077.656
A34: 92948 | B34: sebastian escalante | C34: 573244514045 | D34: 1× Bouquet 6 Rosas Rojas M/10 | E34: Carrera 18 #51-23 Casa | F34: San José | G34: Diana | I34: EXT - Javier | K34: 46089.619 | L34: En Ruta | M34: 03/08/2026 14:51:45 | N34: 03/08/2026 - 14:00:00 | P34: Zona 2 | R34: 46077.671 | S34: 46077.671
A35: 92947 | B35: 3246899919 | C35: 573246899919 | D35: 1× Mini Box Orquidea M/22 | E35: Carrera 47 #102-170 - Apto 201 - torre 2 | F35: Villa Santos | G35: Ble | H35: 573246899919 | I35: Oscar | K35: 46089.603 | L35: Entregado | M35: 03/08/2026 14:27:39 | N35: 03/08/2026 - 02:00:00 | P35: Zona 4 | R35: 46077.682 | S35: 46077.682
A36: 92946 | B36: Santiago Ramón Blanco Estrada | C36: 573028023810 | D36: 1× Corazón Mini Surtido M/12 | E36: Cra7A#45D-54 - Casa | F36: Buenos Aires | G36: Marcela Pérez | H36: 573028023810 | I36: EXT - Javier | K36: 46089.569 | L36: Entregado | M36: 03/08/2026 13:39:50 | N36: 03/08/2026 - 03:00:00 | P36: Zona 2 | R36: 46077.731 | S36: 46077.731
A37: 92943 | B37: Jonathan orozco valencia | C37: 573013506011 | D37: 1× Canasto Mediano Sweet M/4 | E37: Cra 75#78-54 - Torre 7 apto 101 | F37: Paraíso | G37: Alix Gómez | H37: 573013506011 | I37: Elvis | K37: 46089.598 | L37: Entregado | M37: 03/08/2026 14:21:20 | N37: 03/08/2026 - 14:00:00 | P37: Zona 3 | R37: 46077.731 | S37: 46077.731
A38: 92942 | B38: Jonathan orozco valencia | C38: 573013506011 | D38: 1× Guacal Hortensias M/13 | E38: Cra 75#78-54 - Torre 7 apto 101 | F38: Paraíso | G38: Diana valencia | H38: 573013506011 | I38: Elvis | K38: 46089.599 | L38: Entregado | M38: 03/08/2026 14:22:18 | N38: 03/08/2026 - 14:00:00 | P38: Zona 3 | R38: 46077.734 | S38: 46077.734
A39: 92941 | B39: Elizabeth Martinez de Iguaran | C39: 573114239021 | D39: 1× Bouquet 6 Rosas Rojas M/10 | 1× Ferrero Rocher 8 und | E39: Centro comercial Viva, restaurante Olivia - Centro comercial Viva, restaurante Olivia | F39: Centro | G39: Elizabeth Martinez de Iguaran | H39: 573114239021 | K39: 46089.535 | L39: Pendiente | M39: 03/08/2026 12:50:52 | N39: 03/08/2026 - 03:00:00 | P39: Zona 2 | R39: 46077.735 | S39: 46077.735
A40: 92940 | B40: Edgardo Ramírez | C40: 573243585945 | D40: 1× Guacal Hortensias M/13 | E40: Carrera 35 # 56-27 | F40: El Recreo | G40: Yulianis | H40: 573045961095 | I40: Oscar | K40: 46089.591 | L40: Entregado | M40: 03/08/2026 14:10:29 | N40: 03/08/2026 - 14:00:00 | P40: Zona 2 | R40: 46077.735 | S40: 46077.735
...

Sheet Pagos
A1: IDPago | B1: PedidoID | C1: MetodoPago | D1: Valor | E1: FechaPago | H1: TOTAL | I1: MET_PAGO_1 | J1: MET_PAGO_2
A2: 1 | B2: 90000 | C2: EFECTIVO | D2: 100000 | H2: 300000 | I2: 100000 | J2: 200000
A3: 2 | B3: 90000 | C3: TARJETA | D3: 200000

Sheet Caja
A1: Fecha | B1: Base | C1: Efectivo | D1: Gasto | E1: Total_Efectivo | F1: Nueva_Base | G1: Guardado
A2: 46017 | B2: 76000 | C2: 305000 | D2: 148500 | E2: 232500 | F2: 39000
A3: 46018 | B3: 39000 | C3: 890000 | E3: 929000
A4: 46021 | B4: 50600 | D4: 27000 | E4: 23600 | F4: 23600
A5: 46027 | B5: 126600 | C5: 470000 | D5: 201200 | E5: 395400 | F5: 95400
A6: 46028 | B6: 95400 | C6: 111000 | D6: 44500 | E6: 161900 | F6: 70200
A7: 46029 | B7: 70200 | C7: 190000 | D7: 42000 | E7: 218200 | F7: 69200
A8: 46030 | B8: 69200 | C8: 296000 | D8: 24000 | E8: 341200 | F8: 41200
A9: 46031 | B9: 41200 | C9: 18000 | D9: 20000 | E9: 39200 | F9: 39200
A10: 46037 | B10: 104100 | C10: 277000 | D10: 206800 | E10: 174300 | F10: 75000 | G10: 100000
A11: 46038 | B11: 75000 | C11: 0 | E11: 75000 | G11: 0
A12: 46039 | B12: 100000 | C12: 34000 | D12: 65000 | E12: 69000 | F12: 69000 | G12: 0
A13: 46041 | B13: 69000 | C13: 598000 | D13: 220800 | E13: 446200 | F13: 102300 | G13: 400000
A14: 46042 | B14: 102300 | C14: 627000 | D14: 60600 | E14: 668700 | F14: 101700 | G14: 550000
A15: 46043 | B15: 101700 | C15: 38000 | D15: 45000 | E15: 94700 | F15: 92700 | G15: 0
A16: 46044 | B16: 92700 | C16: 150000 | D16: 37000 | E16: 205700 | F16: 56200 | G16: 150000
A17: 46045 | B17: 56200 | D17: 41900 | E17: 14300 | F17: 14300 | G17: 0
A18: 46046 | B18: 0 | C18: 0 | D18: 0 | E18: 0 | F18: 156300 | G18: 0
A19: 46048 | B19: 156300 | C19: 474000 | D19: 64000 | E19: 566300 | F19: 76300 | G19: 490000
A20: 46049 | B20: 76300 | C20: 30000 | D20: 71500 | E20: 34800 | F20: 37800 | G20: 0
A21: 46050 | B21: 37800 | C21: 640000 | D21: 213000 | E21: 464800 | F21: 64800 | G21: 400000
A22: 46051 | B22: 64800 | C22: 518000 | D22: 68000 | E22: 514800 | F22: 74800 | G22: 440000
A23: 46052 | B23: 90800 | C23: 0 | D23: 63000 | E23: 27800 | F23: 29800 | G23: 0
